Workbook
Name FaizDetayTablosu: 'Faiz Tablosu'!$A$1:INDEX('Faiz Tablosu'!$E$1:$E$100,LOOKUP(2,1/('Faiz Tablosu'!$A$1:$A$100<>""),ROW('Faiz Tablosu'!$A$1:$A$100)))

Sheet Faiz Hesaplanan
A1: KANUNİ FAİZ HESAPLA
A2: Ana para: | B2: 100000
A3: Faiz Başlangıç Tarihi | B3: 1 | C3: =IF(OR(B3="",B4="",B4<=MAX('Kaynak Veri'!$B$2:$B$100)),"","DİKKAT: Girilen tarih aralığında kanuni faiz oranı henüz belirlenmemiş bir dönem bulunuyor. "&DAY(MAX(B3,MAX('Kaynak Veri'!$B$2:$B$100)+1))&"."&MONTH(MAX(B3,MAX('Kaynak Veri'!$B$2:$B$100)+1))&"."&YEAR(MAX(B3,MAX('Kaynak Veri'!$B$2:$B$100)+1))&" - "&DAY(B4)&"."&MONTH(B4)&"."&YEAR(B4)&" tarihleri arasında bilinen son kanuni faiz oranı kullanılmıştır.")
A4: Faiz Bitiş Tarihi | B4: =TODAY() -> 46265
A5: Hesaplanan Faiz | B5: ='Faiz Tablosu'!E3 -> 1452295.9 | C5: {=IF(AND(TODAY()>=DATE(2026,7,31),LOOKUP(2,1/('Kaynak Veri'!$A$13:$A$61<=TODAY()),'Kaynak Veri'!$D$13:$D$61)=""),"Güncel döneme ait reeskont faiz oranı henüz girilmemiştir. Lütfen ""Kaynak Veri"" sayfasında 31.07.2026 sonrası yayımlanan reeskont faiz oranlarını güncelleyin.","")}
A6: TOPLAM | B6: =B2+B5 -> 1552295.9

Sheet Faiz Tablosu
A1: FAİZ HESAPLAMA TABLOSU
A2: Dönem Başı | B2: Dönem Sonu | C2: GÜN SAYISI | D2: FAİZ (%) | E2: FAİZ TUTARI
A3: TÜM DÖNEMLER | C3: =SUM(C4:C100) -> 46263 | D3: % | E3: =SUM(E4:E100) -> 1452295.9
A4: =IF(OR('Faiz Hesaplanan'!$B$3="",'Faiz Hesaplanan'!$B$4="",'Faiz Hesaplanan'!$B$3>'Faiz Hesaplanan'!$B$4),"",'Faiz Hesaplanan'!$B$3) -> 1 | B4: =IF(A4="","",MIN('Faiz Hesaplanan'!$B$4,INDEX('Kaynak Veri'!$F$2:$F$61,MATCH(A4,'Kaynak Veri'!$A$2:$A$61,1)))) -> 30681 | C4: =IF(OR(A4="",B4=""),"",B4-A4+1-IF(B4='Faiz Hesaplanan'!$B$4,1,0)-IF(AND(A4<=60,B4>=60),1,0)) -> 30680 | D4: =IF(A4="","",INDEX('Kaynak Veri'!$C$2:$C$61,MATCH(A4,'Kaynak Veri'!$A$2:$A$61,1))) -> 5 | E4: =IF(OR(C4="",D4=""),"",'Faiz Hesaplanan'!$B$2*D4/100*C4/365) -> 420273.97
A5: =IF(OR(B4="",B4>='Faiz Hesaplanan'!$B$4),"",B4+1) -> 30682 | B5: =IF(A5="","",MIN('Faiz Hesaplanan'!$B$4,INDEX('Kaynak Veri'!$F$2:$F$61,MATCH(A5,'Kaynak Veri'!$A$2:$A$61,1)))) -> 35795 | C5: =IF(OR(A5="",B5=""),"",B5-A5+1-IF(B5='Faiz Hesaplanan'!$B$4,1,0)-IF(AND(A5<=60,B5>=60),1,0)) -> 5114 | D5: =IF(A5="","",INDEX('Kaynak Veri'!$C$2:$C$61,MATCH(A5,'Kaynak Veri'!$A$2:$A$61,1))) -> 30 | E5: =IF(OR(C5="",D5=""),"",'Faiz Hesaplanan'!$B$2*D5/100*C5/365) -> 420328.77
A6: =IF(OR(B5="",B5>='Faiz Hesaplanan'!$B$4),"",B5+1) -> 35796 | B6: =IF(A6="","",MIN('Faiz Hesaplanan'!$B$4,INDEX('Kaynak Veri'!$F$2:$F$61,MATCH(A6,'Kaynak Veri'!$A$2:$A$61,1)))) -> 36525 | C6: =IF(OR(A6="",B6=""),"",B6-A6+1-IF(B6='Faiz Hesaplanan'!$B$4,1,0)-IF(AND(A6<=60,B6>=60),1,0)) -> 730 | D6: =IF(A6="","",INDEX('Kaynak Veri'!$C$2:$C$61,MATCH(A6,'Kaynak Veri'!$A$2:$A$61,1))) -> 50 | E6: =IF(OR(C6="",D6=""),"",'Faiz Hesaplanan'!$B$2*D6/100*C6/365) -> 100000
A7: =IF(OR(B6="",B6>='Faiz Hesaplanan'!$B$4),"",B6+1) -> 36526 | B7: =IF(A7="","",MIN('Faiz Hesaplanan'!$B$4,INDEX('Kaynak Veri'!$F$2:$F$61,MATCH(A7,'Kaynak Veri'!$A$2:$A$61,1)))) -> 37437 | C7: =IF(OR(A7="",B7=""),"",B7-A7+1-IF(B7='Faiz Hesaplanan'!$B$4,1,0)-IF(AND(A7<=60,B7>=60),1,0)) -> 912 | D7: =IF(A7="","",INDEX('Kaynak Veri'!$C$2:$C$61,MATCH(A7,'Kaynak Veri'!$A$2:$A$61,1))) -> 60 | E7: =IF(OR(C7="",D7=""),"",'Faiz Hesaplanan'!$B$2*D7/100*C7/365) -> 149917.81
A8: =IF(OR(B7="",B7>='Faiz Hesaplanan'!$B$4),"",B7+1) -> 37438 | B8: =IF(A8="","",MIN('Faiz Hesaplanan'!$B$4,INDEX('Kaynak Veri'!$F$2:$F$61,MATCH(A8,'Kaynak Veri'!$A$2:$A$61,1)))) -> 37802 | C8: =IF(OR(A8="",B8=""),"",B8-A8+1-IF(B8='Faiz Hesaplanan'!$B$4,1,0)-IF(AND(A8<=60,B8>=60),1,0)) -> 365 | D8: =IF(A8="","",INDEX('Kaynak Veri'!$C$2:$C$61,MATCH(A8,'Kaynak Veri'!$A$2:$A$61,1))) -> 55 | E8: =IF(OR(C8="",D8=""),"",'Faiz Hesaplanan'!$B$2*D8/100*C8/365) -> 55000
A9: =IF(OR(B8="",B8>='Faiz Hesaplanan'!$B$4),"",B8+1) -> 37803 | B9: =IF(A9="","",MIN('Faiz Hesaplanan'!$B$4,INDEX('Kaynak Veri'!$F$2:$F$61,MATCH(A9,'Kaynak Veri'!$A$2:$A$61,1)))) -> 37986 | C9: =IF(OR(A9="",B9=""),"",B9-A9+1-IF(B9='Faiz Hesaplanan'!$B$4,1,0)-IF(AND(A9<=60,B9>=60),1,0)) -> 184 | D9: =IF(A9="","",INDEX('Kaynak Veri'!$C$2:$C$61,MATCH(A9,'Kaynak Veri'!$A$2:$A$61,1))) -> 50 | E9: =IF(OR(C9="",D9=""),"",'Faiz Hesaplanan'!$B$2*D9/100*C9/365) -> 25205.479
A10: =IF(OR(B9="",B9>='Faiz Hesaplanan'!$B$4),"",B9+1) -> 37987 | B10: =IF(A10="","",MIN('Faiz Hesaplanan'!$B$4,INDEX('Kaynak Veri'!$F$2:$F$61,MATCH(A10,'Kaynak Veri'!$A$2:$A$61,1)))) -> 38168 | C10: =IF(OR(A10="",B10=""),"",B10-A10+1-IF(B10='Faiz Hesaplanan'!$B$4,1,0)-IF(AND(A10<=60,B10>=60),1,0)) -> 182 | D10: =IF(A10="","",INDEX('Kaynak Veri'!$C$2:$C$61,MATCH(A10,'Kaynak Veri'!$A$2:$A$61,1))) -> 43 | E10: =IF(OR(C10="",D10=""),"",'Faiz Hesaplanan'!$B$2*D10/100*C10/365) -> 21441.096
A11: =IF(OR(B10="",B10>='Faiz Hesaplanan'!$B$4),"",B10+1) -> 38169 | B11: =IF(A11="","",MIN('Faiz Hesaplanan'!$B$4,INDEX('Kaynak Veri'!$F$2:$F$61,MATCH(A11,'Kaynak Veri'!$A$2:$A$61,1)))) -> 38472 | C11: =IF(OR(A11="",B11=""),"",B11-A11+1-IF(B11='Faiz Hesaplanan'!$B$4,1,0)-IF(AND(A11<=60,B11>=60),1,0)) -> 304 | D11: =IF(A11="","",INDEX('Kaynak Veri'!$C$2:$C$61,MATCH(A11,'Kaynak Veri'!$A$2:$A$61,1))) -> 38 | E11: =IF(OR(C11="",D11=""),"",'Faiz Hesaplanan'!$B$2*D11/100*C11/365) -> 31649.315
A12: =IF(OR(B11="",B11>='Faiz Hesaplanan'!$B$4),"",B11+1) -> 38473 | B12: =IF(A12="","",MIN('Faiz Hesaplanan'!$B$4,INDEX('Kaynak Veri'!$F$2:$F$61,MATCH(A12,'Kaynak Veri'!$A$2:$A$61,1)))) -> 38717 | C12: =IF(OR(A12="",B12=""),"",B12-A12+1-IF(B12='Faiz Hesaplanan'!$B$4,1,0)-IF(AND(A12<=60,B12>=60),1,0)) -> 245 | D12: =IF(A12="","",INDEX('Kaynak Veri'!$C$2:$C$61,MATCH(A12,'Kaynak Veri'!$A$2:$A$61,1))) -> 12 | E12: =IF(OR(C12="",D12=""),"",'Faiz Hesaplanan'!$B$2*D12/100*C12/365) -> 8054.7945
A13: =IF(OR(B12="",B12>='Faiz Hesaplanan'!$B$4),"",B12+1) -> 38718 | B13: =IF(A13="","",MIN('Faiz Hesaplanan'!$B$4,INDEX('Kaynak Veri'!$F$2:$F$61,MATCH(A13,'Kaynak Veri'!$A$2:$A$61,1)))) -> 45443 | C13: =IF(OR(A13="",B13=""),"",B13-A13+1-IF(B13='Faiz Hesaplanan'!$B$4,1,0)-IF(AND(A13<=60,B13>=60),1,0)) -> 6726 | D13: =IF(A13="","",INDEX('Kaynak Veri'!$C$2:$C$61,MATCH(A13,'Kaynak Veri'!$A$2:$A$61,1))) -> 9 | E13: =IF(OR(C13="",D13=""),"",'Faiz Hesaplanan'!$B$2*D13/100*C13/365) -> 165846.58
A14: =IF(OR(B13="",B13>='Faiz Hesaplanan'!$B$4),"",B13+1) -> 45444 | B14: =IF(A14="","",MIN('Faiz Hesaplanan'!$B$4,INDEX('Kaynak Veri'!$F$2:$F$61,MATCH(A14,'Kaynak Veri'!$A$2:$A$61,1)))) -> 46233 | C14: =IF(OR(A14="",B14=""),"",B14-A14+1-IF(B14='Faiz Hesaplanan'!$B$4,1,0)-IF(AND(A14<=60,B14>=60),1,0)) -> 790 | D14: =IF(A14="","",INDEX('Kaynak Veri'!$C$2:$C$61,MATCH(A14,'Kaynak Veri'!$A$2:$A$61,1))) -> 24 | E14: =IF(OR(C14="",D14=""),"",'Faiz Hesaplanan'!$B$2*D14/100*C14/365) -> 51945.205
A15: =IF(OR(B14="",B14>='Faiz Hesaplanan'!$B$4),"",B14+1) -> 46234 | B15: =IF(A15="","",MIN('Faiz Hesaplanan'!$B$4,INDEX('Kaynak Veri'!$F$2:$F$61,MATCH(A15,'Kaynak Veri'!$A$2:$A$61,1)))) -> 46265 | C15: =IF(OR(A15="",B15=""),"",B15-A15+1-IF(B15='Faiz Hesaplanan'!$B$4,1,0)-IF(AND(A15<=60,B15>=60),1,0)) -> 31 | D15: =IF(A15="","",INDEX('Kaynak Veri'!$C$2:$C$61,MATCH(A15,'Kaynak Veri'!$A$2:$A$61,1))) -> 31 | E15: =IF(OR(C15="",D15=""),"",'Faiz Hesaplanan'!$B$2*D15/100*C15/365) -> 2632.8767
A16: =IF(OR(B15="",B15>='Faiz Hesaplanan'!$B$4),"",B15+1) | B16: =IF(A16="","",MIN('Faiz Hesaplanan'!$B$4,INDEX('Kaynak Veri'!$F$2:$F$61,MATCH(A16,'Kaynak Veri'!$A$2:$A$61,1)))) | C16: =IF(OR(A16="",B16=""),"",B16-A16+1-IF(B16='Faiz Hesaplanan'!$B$4,1,0)-IF(AND(A16<=60,B16>=60),1,0)) | D16: =IF(A16="","",INDEX('Kaynak Veri'!$C$2:$C$61,MATCH(A16,'Kaynak Veri'!$A$2:$A$61,1))) | E16: =IF(OR(C16="",D16=""),"",'Faiz Hesaplanan'!$B$2*D16/100*C16/365)
... A103: =IF(OR(B102="",B102>='Faiz Hesaplanan'!$B$4),"",B102+1) | B103: =IF(A103="","",MIN('Faiz Hesaplanan'!$B$4,INDEX('Kaynak Veri'!$F$2:$F$61,MATCH(A103,'Kaynak Veri'!$A$2:$A$61,1)))) | C103: =IF(OR(A103="",B103=""),"",B103-A103+1-IF(B103='Faiz Hesaplanan'!$B$4,1,0)-IF(AND(A103<=60,B103>=60),1,0)) | D103: =IF(A103="","",INDEX('Kaynak Veri'!$C$2:$C$61,MATCH(A103,'Kaynak Veri'!$A$2:$A$61,1))) | E103: =IF(OR(C103="",D103=""),"",'Faiz Hesaplanan'!$B$2*D103/100*C103/365)

Sheet Otuz Günlük
A1: HESAPLAMA TARİHİ İTİBARIYLA BORCA İŞLEYECEK OTUZ GÜNLÜK FAİZ TABLOSU
A3: ='Faiz Hesaplanan'!A2 -> Ana para: | C3: ='Faiz Hesaplanan'!B2 -> 100000
A4: ='Faiz Hesaplanan'!A3 -> Faiz Başlangıç Tarihi | C4: ='Faiz Hesaplanan'!B3 -> 1
A5: Hesaplamanın Yapıldığı Tarih | C5: ='Faiz Hesaplanan'!B4 -> 46265
A6: Hesaplamanın yapıldığı tarih itibarıyla otuz günlük süre için işleyecek faiz aşağıdaki gibidir. Ödeme yapılacak güne karşılık gelen toplam miktarın ödenmesi gerekmektedir.
A7: Tarih | B7: Kanuni Faiz Oranı (%) | C7: İşleyen Faiz | D7: Ödenecek Toplam
A8: =IF(OR($C$3="",$C$4="",$C$5=""),"",$C$5) -> 46265 | B8: =$C$3 -> 100000 | C8: =IF(OR($C$3="",$C$4="",$C$5=""),"",IFERROR('Faiz Hesaplanan'!$B$5,"")) -> 1452295.9 | D8: =IF(OR(C8="",$C$3="",$C$4="",$C$5=""),"",$C$3+C8) -> 1552295.9 | E8: {=IF(OR(A8="",$C$3="",$C$4="",$C$5=""),"",IFERROR(LOOKUP(2,1/(('Kaynak Veri'!$A$2:$A$61<=A8-1)*('Kaynak Veri'!$C$2:$C$61<>"")),'Kaynak Veri'!$C$2:$C$61),""))} -> 31
A9: =IF(A8="","",A8+1) -> 46266 | B9: =$C$3 -> 100000 | C9: =IF(OR(A9="",C8="",E9="",$C$3="",$C$4="",$C$5=""),"",C8+$C$3*E9/100/365*IF(A8=60,0,1)) -> 1452380.8 | D9: =IF(OR(C9="",$C$3="",$C$4="",$C$5=""),"",$C$3+C9) -> 1552380.8 | E9: {=IF(OR(A9="",$C$3="",$C$4="",$C$5=""),"",IFERROR(LOOKUP(2,1/(('Kaynak Veri'!$A$2:$A$61<=A9-1)*('Kaynak Veri'!$C$2:$C$61<>"")),'Kaynak Veri'!$C$2:$C$61),""))} -> 31
A10: =IF(A9="","",A9+1) -> 46267 | B10: =$C$3 -> 100000 | C10: =IF(OR(A10="",C9="",E10="",$C$3="",$C$4="",$C$5=""),"",C9+$C$3*E10/100/365*IF(A9=60,0,1)) -> 1452465.8 | D10: =IF(OR(C10="",$C$3="",$C$4="",$C$5=""),"",$C$3+C10) -> 1552465.8 | E10: {=IF(OR(A10="",$C$3="",$C$4="",$C$5=""),"",IFERROR(LOOKUP(2,1/(('Kaynak Veri'!$A$2:$A$61<=A10-1)*('Kaynak Veri'!$C$2:$C$61<>"")),'Kaynak Veri'!$C$2:$C$61),""))} -> 31
A11: =IF(A10="","",A10+1) -> 46268 | B11: =$C$3 -> 100000 | C11: =IF(OR(A11="",C10="",E11="",$C$3="",$C$4="",$C$5=""),"",C10+$C$3*E11/100/365*IF(A10=60,0,1)) -> 1452550.7 | D11: =IF(OR(C11="",$C$3="",$C$4="",$C$5=""),"",$C$3+C11) -> 1552550.7 | E11: {=IF(OR(A11="",$C$3="",$C$4="",$C$5=""),"",IFERROR(LOOKUP(2,1/(('Kaynak Veri'!$A$2:$A$61<=A11-1)*('Kaynak Veri'!$C$2:$C$61<>"")),'Kaynak Veri'!$C$2:$C$61),""))} -> 31
A12: =IF(A11="","",A11+1) -> 46269 | B12: =$C$3 -> 100000 | C12: =IF(OR(A12="",C11="",E12="",$C$3="",$C$4="",$C$5=""),"",C11+$C$3*E12/100/365*IF(A11=60,0,1)) -> 1452635.6 | D12: =IF(OR(C12="",$C$3="",$C$4="",$C$5=""),"",$C$3+C12) -> 1552635.6 | E12: {=IF(OR(A12="",$C$3="",$C$4="",$C$5=""),"",IFERROR(LOOKUP(2,1/(('Kaynak Veri'!$A$2:$A$61<=A12-1)*('Kaynak Veri'!$C$2:$C$61<>"")),'Kaynak Veri'!$C$2:$C$61),""))} -> 31
A13: =IF(A12="","",A12+1) -> 46270 | B13: =$C$3 -> 100000 | C13: =IF(OR(A13="",C12="",E13="",$C$3="",$C$4="",$C$5=""),"",C12+$C$3*E13/100/365*IF(A12=60,0,1)) -> 1452720.5 | D13: =IF(OR(C13="",$C$3="",$C$4="",$C$5=""),"",$C$3+C13) -> 1552720.5 | E13: {=IF(OR(A13="",$C$3="",$C$4="",$C$5=""),"",IFERROR(LOOKUP(2,1/(('Kaynak Veri'!$A$2:$A$61<=A13-1)*('Kaynak Veri'!$C$2:$C$61<>"")),'Kaynak Veri'!$C$2:$C$61),""))} -> 31
A14: =IF(A13="","",A13+1) -> 46271 | B14: =$C$3 -> 100000 | C14: =IF(OR(A14="",C13="",E14="",$C$3="",$C$4="",$C$5=""),"",C13+$C$3*E14/100/365*IF(A13=60,0,1)) -> 1452805.5 | D14: =IF(OR(C14="",$C$3="",$C$4="",$C$5=""),"",$C$3+C14) -> 1552805.5 | E14: {=IF(OR(A14="",$C$3="",$C$4="",$C$5=""),"",IFERROR(LOOKUP(2,1/(('Kaynak Veri'!$A$2:$A$61<=A14-1)*('Kaynak Veri'!$C$2:$C$61<>"")),'Kaynak Veri'!$C$2:$C$61),""))} -> 31
A15: =IF(A14="","",A14+1) -> 46272 | B15: =$C$3 -> 100000 | C15: =IF(OR(A15="",C14="",E15="",$C$3="",$C$4="",$C$5=""),"",C14+$C$3*E15/100/365*IF(A14=60,0,1)) -> 1452890.4 | D15: =IF(OR(C15="",$C$3="",$C$4="",$C$5=""),"",$C$3+C15) -> 1552890.4 | E15: {=IF(OR(A15="",$C$3="",$C$4="",$C$5=""),"",IFERROR(LOOKUP(2,1/(('Kaynak Veri'!$A$2:$A$61<=A15-1)*('Kaynak Veri'!$C$2:$C$61<>"")),'Kaynak Veri'!$C$2:$C$61),""))} -> 31
A16: =IF(A15="","",A15+1) -> 46273 | B16: =$C$3 -> 100000 | C16: =IF(OR(A16="",C15="",E16="",$C$3="",$C$4="",$C$5=""),"",C15+$C$3*E16/100/365*IF(A15=60,0,1)) -> 1452975.3 | D16: =IF(OR(C16="",$C$3="",$C$4="",$C$5=""),"",$C$3+C16) -> 1552975.3 | E16: {=IF(OR(A16="",$C$3="",$C$4="",$C$5=""),"",IFERROR(LOOKUP(2,1/(('Kaynak Veri'!$A$2:$A$61<=A16-1)*('Kaynak Veri'!$C$2:$C$61<>"")),'Kaynak Veri'!$C$2:$C$61),""))} -> 31
A17: =IF(A16="","",A16+1) -> 46274 | B17: =$C$3 -> 100000 | C17: =IF(OR(A17="",C16="",E17="",$C$3="",$C$4="",$C$5=""),"",C16+$C$3*E17/100/365*IF(A16=60,0,1)) -> 1453060.3 | D17: =IF(OR(C17="",$C$3="",$C$4="",$C$5=""),"",$C$3+C17) -> 1553060.3 | E17: {=IF(OR(A17="",$C$3="",$C$4="",$C$5=""),"",IFERROR(LOOKUP(2,1/(('Kaynak Veri'!$A$2:$A$61<=A17-1)*('Kaynak Veri'!$C$2:$C$61<>"")),'Kaynak Veri'!$C$2:$C$61),""))} -> 31
A18: =IF(A17="","",A17+1) -> 46275 | B18: =$C$3 -> 100000 | C18: =IF(OR(A18="",C17="",E18="",$C$3="",$C$4="",$C$5=""),"",C17+$C$3*E18/100/365*IF(A17=60,0,1)) -> 1453145.2 | D18: =IF(OR(C18="",$C$3="",$C$4="",$C$5=""),"",$C$3+C18) -> 1553145.2 | E18: {=IF(OR(A18="",$C$3="",$C$4="",$C$5=""),"",IFERROR(LOOKUP(2,1/(('Kaynak Veri'!$A$2:$A$61<=A18-1)*('Kaynak Veri'!$C$2:$C$61<>"")),'Kaynak Veri'!$C$2:$C$61),""))} -> 31
A19: =IF(A18="","",A18+1) -> 46276 | B19: =$C$3 -> 100000 | C19: =IF(OR(A19="",C18="",E19="",$C$3="",$C$4="",$C$5=""),"",C18+$C$3*E19/100/365*IF(A18=60,0,1)) -> 1453230.1 | D19: =IF(OR(C19="",$C$3="",$C$4="",$C$5=""),"",$C$3+C19) -> 1553230.1 | E19: {=IF(OR(A19="",$C$3="",$C$4="",$C$5=""),"",IFERROR(LOOKUP(2,1/(('Kaynak Veri'!$A$2:$A$61<=A19-1)*('Kaynak Veri'!$C$2:$C$61<>"")),'Kaynak Veri'!$C$2:$C$61),""))} -> 31
A20: =IF(A19="","",A19+1) -> 46277 | B20: =$C$3 -> 100000 | C20: =IF(OR(A20="",C19="",E20="",$C$3="",$C$4="",$C$5=""),"",C19+$C$3*E20/100/365*IF(A19=60,0,1)) -> 1453315.1 | D20: =IF(OR(C20="",$C$3="",$C$4="",$C$5=""),"",$C$3+C20) -> 1553315.1 | E20: {=IF(OR(A20="",$C$3="",$C$4="",$C$5=""),"",IFERROR(LOOKUP(2,1/(('Kaynak Veri'!$A$2:$A$61<=A20-1)*('Kaynak Veri'!$C$2:$C$61<>"")),'Kaynak Veri'!$C$2:$C$61),""))} -> 31
... A38: =IF(A37="","",A37+1) -> 46295 | B38: =$C$3 -> 100000 | C38: =IF(OR(A38="",C37="",E38="",$C$3="",$C$4="",$C$5=""),"",C37+$C$3*E38/100/365*IF(A37=60,0,1)) -> 1454843.8 | D38: =IF(OR(C38="",$C$3="",$C$4="",$C$5=""),"",$C$3+C38) -> 1554843.8 | E38: {=IF(OR(A38="",$C$3="",$C$4="",$C$5=""),"",IFERROR(LOOKUP(2,1/(('Kaynak Veri'!$A$2:$A$61<=A38-1)*('Kaynak Veri'!$C$2:$C$61<>"")),'Kaynak Veri'!$C$2:$C$61),""))} -> 31

Sheet Kaynak Veri
A1: Yürürlük Tarihi | B1: İlga Tarihi | C1: Kanuni Faiz (%) | D1: Kanuni Faize Esas Reeskont Faizi (%) | E1: Değişim | F1: Dönem Sonu | G1: Kesişim | I1: AÇIKLAMALAR
A2: 1 | B2: 30681 | C2: 5 | E2: =IF(C2="","",IF(ROW()=2,1,IF(C2=C1,E1,E1+1))) -> 1 | F2: =IF(E2="","",IFERROR(INDEX($A$2:$A$61,MATCH(E2+1,$E$2:$E$61,0))-1,MAX($B$2:$B$61))) -> 30681 | G2: =IF(E2="","",IF(ROW()=2,1,IF(E2=E1,"",E2))) -> 1 | I2: * Bu sayfa, hesaplama formüllerinde kullanılan faiz ve tarih kaynak verilerini içermektedir.
A3: 30682 | B3: 35795 | C3: 30 | E3: =IF(C3="","",IF(ROW()=2,1,IF(C3=C2,E2,E2+1))) -> 2 | F3: =IF(E3="","",IFERROR(INDEX($A$2:$A$61,MATCH(E3+1,$E$2:$E$61,0))-1,MAX($B$2:$B$61))) -> 35795 | G3: =IF(E3="","",IF(ROW()=2,1,IF(E3=E2,"",E3))) -> 2
A4: 35796 | B4: 36525 | C4: 50 | E4: =IF(C4="","",IF(ROW()=2,1,IF(C4=C3,E3,E3+1))) -> 3 | F4: =IF(E4="","",IFERROR(INDEX($A$2:$A$61,MATCH(E4+1,$E$2:$E$61,0))-1,MAX($B$2:$B$61))) -> 36525 | G4: =IF(E4="","",IF(ROW()=2,1,IF(E4=E3,"",E4))) -> 3 | I4: * Bu sayfadaki hiçbir veri değiştirilmemelidir. Açılıştaki "dış veri engellemesi" uyarısında "İçeriğe İzin Ver" düğmesiyle verilerin güncellenmesi sağlanabilir.
A5: 36526 | B5: 37437 | C5: 60 | E5: =IF(C5="","",IF(ROW()=2,1,IF(C5=C4,E4,E4+1))) -> 4 | F5: =IF(E5="","",IFERROR(INDEX($A$2:$A$61,MATCH(E5+1,$E$2:$E$61,0))-1,MAX($B$2:$B$61))) -> 37437 | G5: =IF(E5="","",IF(ROW()=2,1,IF(E5=E4,"",E5))) -> 4
A6: 37438 | B6: 37802 | C6: 55 | E6: =IF(C6="","",IF(ROW()=2,1,IF(C6=C5,E5,E5+1))) -> 5 | F6: =IF(E6="","",IFERROR(INDEX($A$2:$A$61,MATCH(E6+1,$E$2:$E$61,0))-1,MAX($B$2:$B$61))) -> 37802 | G6: =IF(E6="","",IF(ROW()=2,1,IF(E6=E5,"",E6))) -> 5 | I6: * "Kanuni Faize Esas Reeskont Faizi (%)" başlıklı D sütunundaki veriler resmi kaynaktan alınanarak GitHub aracılığıyla internet üzerinden doldurulmaktadır.
A7: 37803 | B7: 37986 | C7: 50 | E7: =IF(C7="","",IF(ROW()=2,1,IF(C7=C6,E6,E6+1))) -> 6 | F7: =IF(E7="","",IFERROR(INDEX($A$2:$A$61,MATCH(E7+1,$E$2:$E$61,0))-1,MAX($B$2:$B$61))) -> 37986 | G7: =IF(E7="","",IF(ROW()=2,1,IF(E7=E6,"",E7))) -> 6
A8: 37987 | B8: 38168 | C8: 43 | E8: =IF(C8="","",IF(ROW()=2,1,IF(C8=C7,E7,E7+1))) -> 7 | F8: =IF(E8="","",IFERROR(INDEX($A$2:$A$61,MATCH(E8+1,$E$2:$E$61,0))-1,MAX($B$2:$B$61))) -> 38168 | G8: =IF(E8="","",IF(ROW()=2,1,IF(E8=E7,"",E8))) -> 7 | I8: * Verilerin elle doldurulması gereken zorunlu hâllerde aşağıdaki bağlantılar kullanılarak kaynak faiz oranlarına ulaşılabilir.
A9: 38169 | B9: 38472 | C9: 38 | E9: =IF(C9="","",IF(ROW()=2,1,IF(C9=C8,E8,E8+1))) -> 8 | F9: =IF(E9="","",IFERROR(INDEX($A$2:$A$61,MATCH(E9+1,$E$2:$E$61,0))-1,MAX($B$2:$B$61))) -> 38472 | G9: =IF(E9="","",IF(ROW()=2,1,IF(E9=E8,"",E9))) -> 8
A10: 38473 | B10: 38717 | C10: 12 | E10: =IF(C10="","",IF(ROW()=2,1,IF(C10=C9,E9,E9+1))) -> 9 | F10: =IF(E10="","",IFERROR(INDEX($A$2:$A$61,MATCH(E10+1,$E$2:$E$61,0))-1,MAX($B$2:$B$61))) -> 38717 | G10: =IF(E10="","",IF(ROW()=2,1,IF(E10=E9,"",E10))) -> 9
A11: 38718 | B11: 45443 | C11: 9 | E11: =IF(C11="","",IF(ROW()=2,1,IF(C11=C10,E10,E10+1))) -> 10 | F11: =IF(E11="","",IFERROR(INDEX($A$2:$A$61,MATCH(E11+1,$E$2:$E$61,0))-1,MAX($B$2:$B$61))) -> 45443 | G11: =IF(E11="","",IF(ROW()=2,1,IF(E11=E10,"",E11))) -> 10
A12: 45444 | B12: 46233 | C12: 24 | E12: =IF(C12="","",IF(ROW()=2,1,IF(C12=C11,E11,E11+1))) -> 11 | F12: =IF(E12="","",IFERROR(INDEX($A$2:$A$61,MATCH(E12+1,$E$2:$E$61,0))-1,MAX($B$2:$B$61))) -> 46233 | G12: =IF(E12="","",IF(ROW()=2,1,IF(E12=E11,"",E12))) -> 11 | I12: TCMB Reeskont Ve avans oranları tablosu iiçin:
A13: 46234 | B13: 46387 | C13: =IF(D13="","",ROUND(D13*0.8,2)) -> 31 | D13: =IFERROR(_xlfn.XLOOKUP(DATE(2026,7,1),'PowerQuery Veri'!$A:$A,'PowerQuery Veri'!$B:$B),"") -> 38.75 | E13: =IF(C13="","",IF(ROW()=2,1,IF(C13=C12,E12,E12+1))) -> 12 | F13: =IF(E13="","",IFERROR(INDEX($A$2:$A$61,MATCH(E13+1,$E$2:$E$61,0))-1,MAX($B$2:$B$61))) -> 46387 | G13: =IF(E13="","",IF(ROW()=2,1,IF(E13=E12,"",E13))) -> 12 | I13: İnternet erişimine sahip bir cihazla sağdaki karekodu okutun veya aşağıdaki bağlantıya gidin.
A14: 46388 | B14: =IF(C14="","",A15-1) | C14: =IF(D14="","",ROUND(D14*0.8,2)) | D14: =IFERROR(_xlfn.XLOOKUP(A14,'PowerQuery Veri'!$A:$A,'PowerQuery Veri'!$B:$B),"") | E14: =IF(C14="","",IF(ROW()=2,1,IF(C14=C13,E13,E13+1))) | F14: =IF(E14="","",IFERROR(INDEX($A$2:$A$61,MATCH(E14+1,$E$2:$E$61,0))-1,MAX($B$2:$B$61))) | G14: =IF(E14="","",IF(ROW()=2,1,IF(E14=E13,"",E14)))
A15: 46569 | B15: =IF(C15="","",A16-1) | C15: =IF(OR(D15="",D14=""),"",IF(ABS(D15-D14)>=5,ROUND(D15*0.8,2),C14)) | D15: =IFERROR(_xlfn.XLOOKUP(A15,'PowerQuery Veri'!$A:$A,'PowerQuery Veri'!$B:$B),"") | E15: =IF(C15="","",IF(ROW()=2,1,IF(C15=C14,E14,E14+1))) | F15: =IF(E15="","",IFERROR(INDEX($A$2:$A$61,MATCH(E15+1,$E$2:$E$61,0))-1,MAX($B$2:$B$61))) | G15: =IF(E15="","",IF(ROW()=2,1,IF(E15=E14,"",E15)))
A16: 46753 | B16: =IF(C16="","",A17-1) | C16: =IF(D16="","",ROUND(D16*0.8,2)) | D16: =IFERROR(_xlfn.XLOOKUP(A16,'PowerQuery Veri'!$A:$A,'PowerQuery Veri'!$B:$B),"") | E16: =IF(C16="","",IF(ROW()=2,1,IF(C16=C15,E15,E15+1))) | F16: =IF(E16="","",IFERROR(INDEX($A$2:$A$61,MATCH(E16+1,$E$2:$E$61,0))-1,MAX($B$2:$B$61))) | G16: =IF(E16="","",IF(ROW()=2,1,IF(E16=E15,"",E16))) | I16: https://www.tcmb.gov.tr/wps/wcm/connect/TR/TCMB+TR/Main+Menu/Temel+Faaliyetler/Para+Politikasi/Reeskont+ve+Avans+Faiz+Oranlari
A17: 46935 | B17: =IF(C17="","",A18-1) | C17: =IF(OR(D17="",D16=""),"",IF(ABS(D17-D16)>=5,ROUND(D17*0.8,2),C16)) | D17: =IFERROR(_xlfn.XLOOKUP(A17,'PowerQuery Veri'!$A:$A,'PowerQuery Veri'!$B:$B),"") | E17: =IF(C17="","",IF(ROW()=2,1,IF(C17=C16,E16,E16+1))) | F17: =IF(E17="","",IFERROR(INDEX($A$2:$A$61,MATCH(E17+1,$E$2:$E$61,0))-1,MAX($B$2:$B$61))) | G17: =IF(E17="","",IF(ROW()=2,1,IF(E17=E16,"",E17)))
A18: 47119 | B18: =IF(C18="","",A19-1) | C18: =IF(D18="","",ROUND(D18*0.8,2)) | D18: =IFERROR(_xlfn.XLOOKUP(A18,'PowerQuery Veri'!$A:$A,'PowerQuery Veri'!$B:$B),"") | E18: =IF(C18="","",IF(ROW()=2,1,IF(C18=C17,E17,E17+1))) | F18: =IF(E18="","",IFERROR(INDEX($A$2:$A$61,MATCH(E18+1,$E$2:$E$61,0))-1,MAX($B$2:$B$61))) | G18: =IF(E18="","",IF(ROW()=2,1,IF(E18=E17,"",E18)))
A19: 47300 | B19: =IF(C19="","",A20-1) | C19: =IF(OR(D19="",D18=""),"",IF(ABS(D19-D18)>=5,ROUND(D19*0.8,2),C18)) | D19: =IFERROR(_xlfn.XLOOKUP(A19,'PowerQuery Veri'!$A:$A,'PowerQuery Veri'!$B:$B),"") | E19: =IF(C19="","",IF(ROW()=2,1,IF(C19=C18,E18,E18+1))) | F19: =IF(E19="","",IFERROR(INDEX($A$2:$A$61,MATCH(E19+1,$E$2:$E$61,0))-1,MAX($B$2:$B$61))) | G19: =IF(E19="","",IF(ROW()=2,1,IF(E19=E18,"",E19)))
A20: 47484 | B20: =IF(C20="","",A21-1) | C20: =IF(D20="","",ROUND(D20*0.8,2)) | D20: =IFERROR(_xlfn.XLOOKUP(A20,'PowerQuery Veri'!$A:$A,'PowerQuery Veri'!$B:$B),"") | E20: =IF(C20="","",IF(ROW()=2,1,IF(C20=C19,E19,E19+1))) | F20: =IF(E20="","",IFERROR(INDEX($A$2:$A$61,MATCH(E20+1,$E$2:$E$61,0))-1,MAX($B$2:$B$61))) | G20: =IF(E20="","",IF(ROW()=2,1,IF(E20=E19,"",E20)))
A21: 47665 | B21: =IF(C21="","",A22-1) | C21: =IF(OR(D21="",D20=""),"",IF(ABS(D21-D20)>=5,ROUND(D21*0.8,2),C20)) | D21: =IFERROR(_xlfn.XLOOKUP(A21,'PowerQuery Veri'!$A:$A,'PowerQuery Veri'!$B:$B),"") | E21: =IF(C21="","",IF(ROW()=2,1,IF(C21=C20,E20,E20+1))) | F21: =IF(E21="","",IFERROR(INDEX($A$2:$A$61,MATCH(E21+1,$E$2:$E$61,0))-1,MAX($B$2:$B$61))) | G21: =IF(E21="","",IF(ROW()=2,1,IF(E21=E20,"",E21))) | I21: Resmi kaynaktan alınan verilerin olduğu GİtHub sayfası için:
A22: 47849 | B22: =IF(C22="","",A23-1) | C22: =IF(D22="","",ROUND(D22*0.8,2)) | D22: =IFERROR(_xlfn.XLOOKUP(A22,'PowerQuery Veri'!$A:$A,'PowerQuery Veri'!$B:$B),"") | E22: =IF(C22="","",IF(ROW()=2,1,IF(C22=C21,E21,E21+1))) | F22: =IF(E22="","",IFERROR(INDEX($A$2:$A$61,MATCH(E22+1,$E$2:$E$61,0))-1,MAX($B$2:$B$61))) | G22: =IF(E22="","",IF(ROW()=2,1,IF(E22=E21,"",E22))) | L22: İnternet erişimine sahip bir cihazla soldaki karekodu okutun veya aşağıdaki bağlantıya gidin.
A23: 48030 | B23: =IF(C23="","",A24-1) | C23: =IF(OR(D23="",D22=""),"",IF(ABS(D23-D22)>=5,ROUND(D23*0.8,2),C22)) | D23: =IFERROR(_xlfn.XLOOKUP(A23,'PowerQuery Veri'!$A:$A,'PowerQuery Veri'!$B:$B),"") | E23: =IF(C23="","",IF(ROW()=2,1,IF(C23=C22,E22,E22+1))) | F23: =IF(E23="","",IFERROR(INDEX($A$2:$A$61,MATCH(E23+1,$E$2:$E$61,0))-1,MAX($B$2:$B$61))) | G23: =IF(E23="","",IF(ROW()=2,1,IF(E23=E22,"",E23)))
A24: 48214 | B24: =IF(C24="","",A25-1) | C24: =IF(D24="","",ROUND(D24*0.8,2)) | D24: =IFERROR(_xlfn.XLOOKUP(A24,'PowerQuery Veri'!$A:$A,'PowerQuery Veri'!$B:$B),"") | E24: =IF(C24="","",IF(ROW()=2,1,IF(C24=C23,E23,E23+1))) | F24: =IF(E24="","",IFERROR(INDEX($A$2:$A$61,MATCH(E24+1,$E$2:$E$61,0))-1,MAX($B$2:$B$61))) | G24: =IF(E24="","",IF(ROW()=2,1,IF(E24=E23,"",E24)))
A25: 48396 | B25: =IF(C25="","",A26-1) | C25: =IF(OR(D25="",D24=""),"",IF(ABS(D25-D24)>=5,ROUND(D25*0.8,2),C24)) | D25: =IFERROR(_xlfn.XLOOKUP(A25,'PowerQuery Veri'!$A:$A,'PowerQuery Veri'!$B:$B),"") | E25: =IF(C25="","",IF(ROW()=2,1,IF(C25=C24,E24,E24+1))) | F25: =IF(E25="","",IFERROR(INDEX($A$2:$A$61,MATCH(E25+1,$E$2:$E$61,0))-1,MAX($B$2:$B$61))) | G25: =IF(E25="","",IF(ROW()=2,1,IF(E25=E24,"",E25))) | L25: https://raw.githubusercontent.com/ferhatbkr/tcmb_reeskont_faizi/refs/heads/main/esas.txt
A26: 48580 | B26: =IF(C26="","",A27-1) | C26: =IF(D26="","",ROUND(D26*0.8,2)) | D26: =IFERROR(_xlfn.XLOOKUP(A26,'PowerQuery Veri'!$A:$A,'PowerQuery Veri'!$B:$B),"") | E26: =IF(C26="","",IF(ROW()=2,1,IF(C26=C25,E25,E25+1))) | F26: =IF(E26="","",IFERROR(INDEX($A$2:$A$61,MATCH(E26+1,$E$2:$E$61,0))-1,MAX($B$2:$B$61))) | G26: =IF(E26="","",IF(ROW()=2,1,IF(E26=E25,"",E26)))
A27: 48761 | B27: =IF(C27="","",A28-1) | C27: =IF(OR(D27="",D26=""),"",IF(ABS(D27-D26)>=5,ROUND(D27*0.8,2),C26)) | D27: =IFERROR(_xlfn.XLOOKUP(A27,'PowerQuery Veri'!$A:$A,'PowerQuery Veri'!$B:$B),"") | E27: =IF(C27="","",IF(ROW()=2,1,IF(C27=C26,E26,E26+1))) | F27: =IF(E27="","",IFERROR(INDEX($A$2:$A$61,MATCH(E27+1,$E$2:$E$61,0))-1,MAX($B$2:$B$61))) | G27: =IF(E27="","",IF(ROW()=2,1,IF(E27=E26,"",E27)))
A28: 48945 | B28: =IF(C28="","",A29-1) | C28: =IF(D28="","",ROUND(D28*0.8,2)) | D28: =IFERROR(_xlfn.XLOOKUP(A28,'PowerQuery Veri'!$A:$A,'PowerQuery Veri'!$B:$B),"") | E28: =IF(C28="","",IF(ROW()=2,1,IF(C28=C27,E27,E27+1))) | F28: =IF(E28="","",IFERROR(INDEX($A$2:$A$61,MATCH(E28+1,$E$2:$E$61,0))-1,MAX($B$2:$B$61))) | G28: =IF(E28="","",IF(ROW()=2,1,IF(E28=E27,"",E28)))
A29: 49126 | B29: =IF(C29="","",A30-1) | C29: =IF(OR(D29="",D28=""),"",IF(ABS(D29-D28)>=5,ROUND(D29*0.8,2),C28)) | D29: =IFERROR(_xlfn.XLOOKUP(A29,'PowerQuery Veri'!$A:$A,'PowerQuery Veri'!$B:$B),"") | E29: =IF(C29="","",IF(ROW()=2,1,IF(C29=C28,E28,E28+1))) | F29: =IF(E29="","",IFERROR(INDEX($A$2:$A$61,MATCH(E29+1,$E$2:$E$61,0))-1,MAX($B$2:$B$61))) | G29: =IF(E29="","",IF(ROW()=2,1,IF(E29=E28,"",E29)))
A30: 49310 | B30: =IF(C30="","",A31-1) | C30: =IF(D30="","",ROUND(D30*0.8,2)) | D30: =IFERROR(_xlfn.XLOOKUP(A30,'PowerQuery Veri'!$A:$A,'PowerQuery Veri'!$B:$B),"") | E30: =IF(C30="","",IF(ROW()=2,1,IF(C30=C29,E29,E29+1))) | F30: =IF(E30="","",IFERROR(INDEX($A$2:$A$61,MATCH(E30+1,$E$2:$E$61,0))-1,MAX($B$2:$B$61))) | G30: =IF(E30="","",IF(ROW()=2,1,IF(E30=E29,"",E30)))
A31: 49491 | B31: =IF(C31="","",A32-1) | C31: =IF(OR(D31="",D30=""),"",IF(ABS(D31-D30)>=5,ROUND(D31*0.8,2),C30)) | D31: =IFERROR(_xlfn.XLOOKUP(A31,'PowerQuery Veri'!$A:$A,'PowerQuery Veri'!$B:$B),"") | E31: =IF(C31="","",IF(ROW()=2,1,IF(C31=C30,E30,E30+1))) | F31: =IF(E31="","",IFERROR(INDEX($A$2:$A$61,MATCH(E31+1,$E$2:$E$61,0))-1,MAX($B$2:$B$61))) | G31: =IF(E31="","",IF(ROW()=2,1,IF(E31=E30,"",E31))) | I31: Kanuni faizin belirlenme usulü, aşağıdaki kanun hükmüyle düzenlenmektedir:
A32: 49675 | B32: =IF(C32="","",A33-1) | C32: =IF(D32="","",ROUND(D32*0.8,2)) | D32: =IFERROR(_xlfn.XLOOKUP(A32,'PowerQuery Veri'!$A:$A,'PowerQuery Veri'!$B:$B),"") | E32: =IF(C32="","",IF(ROW()=2,1,IF(C32=C31,E31,E31+1))) | F32: =IF(E32="","",IFERROR(INDEX($A$2:$A$61,MATCH(E32+1,$E$2:$E$61,0))-1,MAX($B$2:$B$61))) | G32: =IF(E32="","",IF(ROW()=2,1,IF(E32=E31,"",E32))) | I32: 3095 Sayılı Kanuni Faiz ve Temerrüt Faizine İlişkin Kanun
A33: 49857 | B33: =IF(C33="","",A34-1) | C33: =IF(OR(D33="",D32=""),"",IF(ABS(D33-D32)>=5,ROUND(D33*0.8,2),C32)) | D33: =IFERROR(_xlfn.XLOOKUP(A33,'PowerQuery Veri'!$A:$A,'PowerQuery Veri'!$B:$B),"") | E33: =IF(C33="","",IF(ROW()=2,1,IF(C33=C32,E32,E32+1))) | F33: =IF(E33="","",IFERROR(INDEX($A$2:$A$61,MATCH(E33+1,$E$2:$E$61,0))-1,MAX($B$2:$B$61))) | G33: =IF(E33="","",IF(ROW()=2,1,IF(E33=E32,"",E33))) | I33: Kanuni Faiz Madde 1 – (Değişik:16/7/2026-7589/10 md.) 11/1/2011 tarihli ve 6098 sayılı Türk Borçlar Kanunu ile 13/1/2011 tarihli ve 6102 sayılı Türk Ticaret Kanununa göre faiz ödenmesi gereken hallerde, miktarı sözleşme ile tespit edilmemişse bu ödeme yıllık, Türkiye Cumhuriyet Merkez Bankasının önceki yılın 31 Aralık günü kısa vadeli kredi işlemlerinde uyguladığı reeskont oranının yüzde sekseni üzerinden yapılır. Söz konusu reeskont oranı, 30 Haziran günü önceki yılın 31 Aralık günü uygulanan reeskont oranından beş puan veya daha çok farklı ise, yılın ikinci yarısında 30 Haziran günü belirlenen oranın yüzde sekseni geçerli olur.
A34: 50041 | B34: =IF(C34="","",A35-1) | C34: =IF(D34="","",ROUND(D34*0.8,2)) | D34: =IFERROR(_xlfn.XLOOKUP(A34,'PowerQuery Veri'!$A:$A,'PowerQuery Veri'!$B:$B),"") | E34: =IF(C34="","",IF(ROW()=2,1,IF(C34=C33,E33,E33+1))) | F34: =IF(E34="","",IFERROR(INDEX($A$2:$A$61,MATCH(E34+1,$E$2:$E$61,0))-1,MAX($B$2:$B$61))) | G34: =IF(E34="","",IF(ROW()=2,1,IF(E34=E33,"",E34)))
A35: 50222 | B35: =IF(C35="","",A36-1) | C35: =IF(OR(D35="",D34=""),"",IF(ABS(D35-D34)>=5,ROUND(D35*0.8,2),C34)) | D35: =IFERROR(_xlfn.XLOOKUP(A35,'PowerQuery Veri'!$A:$A,'PowerQuery Veri'!$B:$B),"") | E35: =IF(C35="","",IF(ROW()=2,1,IF(C35=C34,E34,E34+1))) | F35: =IF(E35="","",IFERROR(INDEX($A$2:$A$61,MATCH(E35+1,$E$2:$E$61,0))-1,MAX($B$2:$B$61))) | G35: =IF(E35="","",IF(ROW()=2,1,IF(E35=E34,"",E35)))
A36: 50406 | B36: =IF(C36="","",A37-1) | C36: =IF(D36="","",ROUND(D36*0.8,2)) | D36: =IFERROR(_xlfn.XLOOKUP(A36,'PowerQuery Veri'!$A:$A,'PowerQuery Veri'!$B:$B),"") | E36: =IF(C36="","",IF(ROW()=2,1,IF(C36=C35,E35,E35+1))) | F36: =IF(E36="","",IFERROR(INDEX($A$2:$A$61,MATCH(E36+1,$E$2:$E$61,0))-1,MAX($B$2:$B$61))) | G36: =IF(E36="","",IF(ROW()=2,1,IF(E36=E35,"",E36)))
A37: 50587 | B37: =IF(C37="","",A38-1) | C37: =IF(OR(D37="",D36=""),"",IF(ABS(D37-D36)>=5,ROUND(D37*0.8,2),C36)) | D37: =IFERROR(_xlfn.XLOOKUP(A37,'PowerQuery Veri'!$A:$A,'PowerQuery Veri'!$B:$B),"") | E37: =IF(C37="","",IF(ROW()=2,1,IF(C37=C36,E36,E36+1))) | F37: =IF(E37="","",IFERROR(INDEX($A$2:$A$61,MATCH(E37+1,$E$2:$E$61,0))-1,MAX($B$2:$B$61))) | G37: =IF(E37="","",IF(ROW()=2,1,IF(E37=E36,"",E37)))
A38: 50771 | B38: =IF(C38="","",A39-1) | C38: =IF(D38="","",ROUND(D38*0.8,2)) | D38: =IFERROR(_xlfn.XLOOKUP(A38,'PowerQuery Veri'!$A:$A,'PowerQuery Veri'!$B:$B),"") | E38: =IF(C38="","",IF(ROW()=2,1,IF(C38=C37,E37,E37+1))) | F38: =IF(E38="","",IFERROR(INDEX($A$2:$A$61,MATCH(E38+1,$E$2:$E$61,0))-1,MAX($B$2:$B$61))) | G38: =IF(E38="","",IF(ROW()=2,1,IF(E38=E37,"",E38)))
A39: 50952 | B39: =IF(C39="","",A40-1) | C39: =IF(OR(D39="",D38=""),"",IF(ABS(D39-D38)>=5,ROUND(D39*0.8,2),C38)) | D39: =IFERROR(_xlfn.XLOOKUP(A39,'PowerQuery Veri'!$A:$A,'PowerQuery Veri'!$B:$B),"") | E39: =IF(C39="","",IF(ROW()=2,1,IF(C39=C38,E38,E38+1))) | F39: =IF(E39="","",IFERROR(INDEX($A$2:$A$61,MATCH(E39+1,$E$2:$E$61,0))-1,MAX($B$2:$B$61))) | G39: =IF(E39="","",IF(ROW()=2,1,IF(E39=E38,"",E39)))
A40: 51136 | B40: =IF(C40="","",A41-1) | C40: =IF(D40="","",ROUND(D40*0.8,2)) | D40: =IFERROR(_xlfn.XLOOKUP(A40,'PowerQuery Veri'!$A:$A,'PowerQuery Veri'!$B:$B),"") | E40: =IF(C40="","",IF(ROW()=2,1,IF(C40=C39,E39,E39+1))) | F40: =IF(E40="","",IFERROR(INDEX($A$2:$A$61,MATCH(E40+1,$E$2:$E$61,0))-1,MAX($B$2:$B$61))) | G40: =IF(E40="","",IF(ROW()=2,1,IF(E40=E39,"",E40)))
...

Sheet PowerQuery Veri
A1: Tarih | B1: Oran | C1: Bu elektronik tablonun çalışması için bu sayfayı düzenlemeyin, silmeyin, yeniden adlandırmayın veya başka herhangi bir işlem yapmayın.
A2: 46023 | B2: 38.75
A3: 46204 | B3: 38.75
